<?xml version="1.0" ?>
<!-- =================================================================================== -->
<!-- |    This document was autogenerated by xacro from exo.xacro                      | -->
<!-- |    EDITING THIS FILE BY HAND IS NOT RECOMMENDED                                 | -->
<!-- =================================================================================== -->
<robot name="exoskeleton_leg">
  <!-- Base Link -->
  <link name="base_link">
    <inertial>
      <mass value="1.0"/>
      <inertia ixx="0.01" ixy="0" ixz="0" iyy="0.01" iyz="0" izz="0.01"/>
    </inertial>
    <visual>
      <geometry>
        <box size="0.1 0.1 0.05"/>
      </geometry>
      <material name="black">
        <color rgba="0 0 0 1"/>
      </material>
    </visual>
    <collision>
      <geometry>
        <box size="0.1 0.1 0.05"/>
      </geometry>
    </collision>
  </link>
  <!-- Hip Joint -->
  <joint name="hip_joint" type="revolute">
    <parent link="base_link"/>
    <child link="thigh_link"/>
    <!-- Position hip joint at the bottom of base_link (assuming base_link height is negligible) -->
    <origin rpy="0 0 0" xyz="0 0 -.15"/>
    <axis xyz="0 0 1"/>
    <dynamics damping="0.1" friction="0.01"/>
    <!-- 
    ISO 13485 Compliance: Prevents Excessive internal rotation (> 45°) and excessive external rotation (> 45°)
    internal rotation: 0 ~ 45°
    external rotation: 0 ~ 45°
    walking: 20° ~ 30°
  -->
    <limit effort="350" lower="-0.7" upper="0.7" velocity="3.0"/>
    <!-- 0.7rad ~= 40° -->
    <safety_controller k_velocity="20" soft_lower_limit="-0.665" soft_upper_limit="0.665"/>
    <!-- 0.665rad ~= 38° -->
  </joint>
  <!-- Thigh Link -->
  <link name="thigh_link">
    <visual>
      <geometry>
        <cylinder length="0.3" radius="0.03"/>
      </geometry>
      <material name="blue">
        <color rgba="0 0 0.8 1"/>
      </material>
    </visual>
    <collision>
      <geometry>
        <cylinder length="0.3" radius="0.03"/>
      </geometry>
    </collision>
    <inertial>
      <mass value="0.5"/>
      <inertia ixx="0.005" ixy="0" ixz="0" iyy="0.005" iyz="0" izz="0.005"/>
    </inertial>
  </link>
  <!-- Knee Joint -->
  <joint name="knee_joint" type="revolute">
    <parent link="thigh_link"/>
    <child link="shank_link"/>
    <!-- Position knee joint at the end of thigh_link -->
    <origin rpy="0 0 0" xyz="0 0 -0.15"/>
    <!-- Negative Z to move down from thigh_link -->
    <axis xyz="0 1 0"/>
    <dynamics damping="0.05" friction="0.005"/>
    <!-- 
    ISO 13485 Compliance: Prevents overextension (lower="0") and excessive flexion (upper="2.0" ≈ 150°).
    walking: 0~1.22 rad
    stairs: 0~1.57 rad 
    exercise: 0~2.09 rad 
  -->
    <limit effort="300" lower="0" upper="2" velocity="2.5"/>
    <safety_controller k_velocity="30" soft_lower_limit="0.05" soft_upper_limit="1.9"/>
  </joint>
  <!-- Shank Link -->
  <link name="shank_link">
    <visual>
      <geometry>
        <cylinder length="0.35" radius="0.025"/>
      </geometry>
      <origin rpy="0 0 0" xyz="0 0 -0.175"/>
      <material name="red">
        <color rgba="0.8 0 0 1"/>
      </material>
    </visual>
    <collision>
      <geometry>
        <cylinder length="0.35" radius="0.025"/>
      </geometry>
    </collision>
    <inertial>
      <mass value="0.3"/>
      <inertia ixx="0.003" ixy="0" ixz="0" iyy="0.003" iyz="0" izz="0.003"/>
    </inertial>
  </link>
  <!-- Ankle Joint -->
  <joint name="ankle_joint" type="revolute">
    <parent link="shank_link"/>
    <child link="foot_link"/>
    <!-- Position ankle joint at the end of shank_link -->
    <origin rpy="0 0 0" xyz="0 0 -0.35"/>
    <!-- Negative Z to move down from shank_link -->
    <axis xyz="0 1 0"/>
    <dynamics damping="0.03" friction="0.005"/>
    <!--
    typical ROM for ankle joint is 20° dorsiflexion and 50° plantarflexion
    Dorsiflexion (upward movement)‌: 0 - 20° (0 - 0.35rad)
    Plantarflexion (downward movement)‌: 0 - 55° (0 - 0.96rad)
  -->
    <limit effort="300" lower="-0.3" upper="0.3" velocity="3.0"/>
    <safety_controller k_velocity="50" soft_lower_limit="-0.25" soft_upper_limit="0.25"/>
  </joint>
  <!-- Foot Link -->
  <link name="foot_link">
    <visual>
      <geometry>
        <box size="0.15 0.05 0.01"/>
      </geometry>
      <material name="gray">
        <color rgba="0.5 0.5 0.5 1"/>
      </material>
    </visual>
    <collision>
      <geometry>
        <box size="0.15 0.05 0.01"/>
      </geometry>
    </collision>
    <inertial>
      <mass value="0.1"/>
      <inertia ixx="0.0001" ixy="0" ixz="0" iyy="0.0001" iyz="0" izz="0.0001"/>
    </inertial>
  </link>
  <!-- Transmissions (unchanged) -->
  <transmission name="hip_transmission">
    <type>transmission_interface/SimpleTransmission</type>
    <actuator name="hip_motor">
      <hardwareInterface>Effort</hardwareInterface>
    </actuator>
    <joint name="hip_joint"/>
  </transmission>
  <transmission name="knee_transmission">
    <type>transmission_interface/SimpleTransmission</type>
    <actuator name="knee_motor">
      <hardwareInterface>Effort</hardwareInterface>
    </actuator>
    <joint name="knee_joint"/>
  </transmission>
  <transmission name="ankle_transmission">
    <type>transmission_interface/SimpleTransmission</type>
    <actuator name="ankle_motor">
      <hardwareInterface>Effort</hardwareInterface>
    </actuator>
    <joint name="ankle_joint"/>
  </transmission>
  <!-- Gazebo plugins (unchanged) -->
  <gazebo reference="thigh_link">
    <sensor name="thigh_imu" type="imu">
      <always_on>true</always_on>
      <update_rate>100</update_rate>
    </sensor>
  </gazebo>
  <gazebo reference="foot_link">
    <sensor name="foot_contact" type="contact">
      <always_on>true</always_on>
      <update_rate>50</update_rate>
    </sensor>
  </gazebo>
  <gazebo>
    <plugin filename="libgazebo_ros_control.so" name="gazebo_ros_control">
      <robotNamespace>/exoskeleton</robotNamespace>
    </plugin>
  </gazebo>
</robot>
