<?xml version="1.0" ?>
<!-- =================================================================================== -->
<!-- |    This document was autogenerated by xacro from exo.xacro                      | -->
<!-- |    EDITING THIS FILE BY HAND IS NOT RECOMMENDED                                 | -->
<!-- =================================================================================== -->
<robot name="exo_urdf">
  <!-- Base structure mass -->
  <!-- Robot Definition -->
  <!-- Base Link with Motor Mass -->
  <link name="base_link">
    <inertial>
      <origin rpy="0 0 0" xyz="0 0 0"/>
      <mass value="4.0"/>
      <!-- 1.0kg base + 3.0kg motor -->
      <!-- Empirical inertia for 3kg motor (scaled from original) -->
      <inertia ixx="0.04" ixy="0" ixz="0" iyy="0.04" iyz="0" izz="0.025"/>
    </inertial>
    <visual>
      <geometry>
        <box size="0.1 0.1 0.05"/>
      </geometry>
      <material name="black">
        <color rgba="0 0 0 1"/>
      </material>
    </visual>
    <collision>
      <geometry>
        <box size="0.1 0.1 0.05"/>
      </geometry>
    </collision>
  </link>
  <!-- Gazebo Configurations -->
  <gazebo reference="base_link">
    <material>Gazebo/DarkGrey</material>
    <mu1>0.5</mu1>
    <mu2>0.5</mu2>
    <kp>500000</kp>
    <!-- Reduced stiffness for heavy mass -->
    <kd>500</kd>
    <!-- Increased damping -->
  </gazebo>
  <!-- Heavy Hip Joint -->
  <joint name="hip_joint" type="revolute">
    <parent link="base_link"/>
    <child link="thigh_link"/>
    <!-- Positioned 2.5cm below base center-->
    <origin rpy="0 0 0" xyz="0 0 -0.025"/>
    <!-- Z-axis rotation for flexion/extension -->
    <axis xyz="0 0 1"/>
    <!-- Limits for ISO 13485 Compliance -->
    <limit effort="400" lower="-0.7854" upper="0.7854" velocity="2"/>
    <!-- 300Nm torque (heavy motor), Conservative 2 rad/s (~115°/s), +-45° hard limit -->
    <safety_controller k_velocity="100" soft_lower_limit="-0.75" soft_upper_limit="0.75"/>
    <!-- Stronger braking -->
    <!-- -43° soft limit -->
    <!-- +43° soft limit -->
    <!-- High damping for motor inertia -->
    <dynamics damping="1.5" friction="0.3"/>
  </joint>
  <!-- Increased viscous damping -->
  <!-- Higher static friction -->
  <!-- Thigh Link with 3kg Motor Mass -->
  <link name="thigh_link">
    <visual>
      <geometry>
        <cylinder length="0.3" radius="0.03"/>
      </geometry>
      <origin rpy="0 0 0" xyz="0 0 -0.15"/>
      <material name="blue">
        <color rgba="0 0 0.8 1"/>
      </material>
    </visual>
    <collision>
      <geometry>
        <cylinder length="0.3" radius="0.03"/>
      </geometry>
      <origin rpy="0 0 0" xyz="0 0 -0.15"/>
    </collision>
    <!-- Optimized Inertial for 3.5kg Total Mass -->
    <inertial>
      <origin xyz="0 0 0.2786"/>
      <!-- COM: (0.5*0.15 + 3*0.3)/3.5 -->
      <mass value="3.5"/>
      <inertia ixx="0.1135" ixy="0" ixz="0" iyy="0.1135" iyz="0" izz="0.000225"/>
      <!-- Dominated by axial motor inertia -->
    </inertial>
  </link>
  <gazebo reference="thigh_link">
    <mu1>0.8</mu1>
    <!-- Increased friction for heavy load -->
    <mu2>0.8</mu2>
    <kp>2000000</kp>
    <!-- Higher stiffness -->
    <kd>2000</kd>
    <!-- Increased damping -->
  </gazebo>
  <!-- Knee Joint -->
  <joint name="knee_joint" type="revolute">
    <parent link="thigh_link"/>
    <child link="shank_link"/>
    <!-- Corrected Origin (0.3m from parent origin) -->
    <origin rpy="0 0 0" xyz="0 0 -0.3"/>
    <!-- End of 0.3m thigh cylinder -->
    <!-- Mediolateral Rotation Axis (Y-axis for sagittal plane motion) -->
    <axis xyz="0 1 0"/>
    <!-- Enhanced Dynamics for 3kg Motor -->
    <dynamics damping="1.2" friction="0.4"/>
    <!-- 8x higher damping than before -->
    <!-- ISO 13485 Compliant Limits -->
    <!-- 150° = 2.618 rad -->
    <limit effort="350" lower="0" upper="2.3" velocity="2.0"/>
    <!-- Stronger braking force -->
    <!-- 5.7° buffer for low limit-->
    <!-- 6.8° buffer for upper limit-->
    <safety_controller k_velocity="150" soft_lower_limit="0.05" soft_upper_limit="2.2"/>
  </joint>
  <!-- Shank Link -->
  <link name="shank_link">
    <visual>
      <geometry>
        <cylinder length="0.35" radius="0.025"/>
      </geometry>
      <!-- Center cylinder at link origin -->
      <origin rpy="0 0 0" xyz="0 0 -0.175"/>
      <material name="red">
        <color rgba="0.8 0 0 1"/>
      </material>
    </visual>
    <collision>
      <geometry>
        <cylinder length="0.35" radius="0.025"/>
      </geometry>
      <!-- Match visual origin -->
      <origin rpy="0 0 0" xyz="0 0 0"/>
    </collision>
    <!-- Optimized Inertial Properties -->
    <inertial>
      <origin xyz="0 0 0.175"/>
      <!-- COM at geometric center -->
      <mass value="0.25"/>
      <!-- Increased from 0.3kg for safety margin -->
      <!--
        Cylinder inertia formulas (r=0.025m, h=0.35m):
        I_xx = I_yy = (1/12)*m*(3r² + h²) = 0.00257
        I_zz = (1/2)*m*r² = 0.000078
      -->
      <inertia ixx="0.00257" ixy="0" ixz="0" iyy="0.00257" iyz="0" izz="0.000078"/>
    </inertial>
  </link>
  <!-- Shank Link Gazebo Attr -->
  <gazebo reference="shank_link">
    <material>Gazebo/Red</material>
    <mu1>0.6</mu1>
    <!-- Increased friction for fabric grip -->
    <mu2>0.6</mu2>
    <kp>50000</kp>
    <!-- Reduced stiffness for stability -->
    <kd>500</kd>
    <!-- Increased damping -->
  </gazebo>
  <!-- Ankle Joint -->
  <joint name="ankle_joint" type="revolute">
    <parent link="shank_link"/>
    <child link="foot_link"/>
    <!-- Position ankle joint at the end of shank_link -->
    <origin rpy="0 0 0" xyz="0 0 -0.35"/>
    <!-- Negative Z to move down from shank_link -->
    <axis xyz="0 1 0"/>
    <dynamics damping="0.8" friction="0.1"/>
    <!--
      typical ROM for ankle joint is 20° dorsiflexion and 50° plantarflexion
      Dorsiflexion (upward movement)‌: 0 - 20° (0 - 0.35rad)
      Plantarflexion (downward movement)‌: 0 - 55° (0 - 0.96rad)
    -->
    <limit effort="150" lower="-0.3" upper="0.3" velocity="3.0"/>
    <safety_controller k_velocity="100" soft_lower_limit="-0.25" soft_upper_limit="0.25"/>
  </joint>
  <!-- Foot Link -->
  <link name="foot_link">
    <visual>
      <geometry>
        <box size="0.15 0.05 0.01"/>
      </geometry>
      <material name="gray">
        <color rgba="0.5 0.5 0.5 1"/>
      </material>
    </visual>
    <collision>
      <geometry>
        <box size="0.15 0.05 0.01"/>
      </geometry>
    </collision>
    <inertial>
      <mass value="0.1"/>
      <inertia ixx="0.0001" ixy="0" ixz="0" iyy="0.0001" iyz="0" izz="0.0001"/>
    </inertial>
  </link>
  <!-- Foot Link Gazebo Attr -->
  <gazebo reference="foot_link">
    <mu1>0.2</mu1>
    <!-- Contact Friction Coefficient -->
    <mu2>0.2</mu2>
    <kp>1000000</kp>
    <!-- Contact Stiffness [N/m] -->
    <kd>100</kd>
    <!-- Contact Damping [N·s/m] -->
  </gazebo>
  <!-- Gazebo Transmissions -->
  <transmission name="hip_transmission">
    <type>transmission_interface/SimpleTransmission</type>
    <joint name="hip_joint">
      <hardwareInterface>hardware_interface/EffortJointInterface</hardwareInterface>
    </joint>
    <actuator name="hip_motor">
      <mechanicalReduction>1</mechanicalReduction>
      <hardwareInterface>hardware_interface/EffortJointInterface</hardwareInterface>
    </actuator>
  </transmission>
  <transmission name="knee_transmission">
    <type>transmission_interface/SimpleTransmission</type>
    <joint name="knee_joint">
      <hardwareInterface>hardware_interface/EffortJointInterface</hardwareInterface>
    </joint>
    <actuator name="knee_motor">
      <mechanicalReduction>1</mechanicalReduction>
      <hardwareInterface>hardware_interface/EffortJointInterface</hardwareInterface>
    </actuator>
  </transmission>
  <transmission name="ankle_transmission">
    <type>transmission_interface/SimpleTransmission</type>
    <joint name="ankle_joint">
      <hardwareInterface>hardware_interface/EffortJointInterface</hardwareInterface>
    </joint>
    <actuator name="ankle_motor">
      <mechanicalReduction>1</mechanicalReduction>
      <hardwareInterface>hardware_interface/EffortJointInterface</hardwareInterface>
    </actuator>
  </transmission>
  <!-- Gazebo Sensor Plugin -->
  <gazebo reference="thigh_link">
    <sensor name="thigh_imu_sensor" type="imu">
      <always_on>true</always_on>
      <update_rate>100</update_rate>
      <plugin filename="libgazebo_ros_imu_sensor.so" name="thigh_imu_sensor_plugin">
        <ros>
          <namespace>/sensors</namespace>
          <remapping>~/out:=imu/thigh</remapping>
        </ros>
        <frame_name>thigh_link</frame_name>
        <static_reference>true</static_reference>
        <gravity>true</gravity>
        <orientation_reference_frame>ENU</orientation_reference_frame>
      </plugin>
      <imu>
        <noise>
          <type>gaussian</type>
          <rate>
            <mean>0.0</mean>
            <stddev>0.0002</stddev>
          </rate>
          <accel>
            <mean>0.0</mean>
            <stddev>0.017</stddev>
          </accel>
        </noise>
      </imu>
    </sensor>
  </gazebo>
  <gazebo reference="shank_link">
    <sensor name="shank_imu_sensor" type="imu">
      <always_on>true</always_on>
      <update_rate>100</update_rate>
      <plugin filename="libgazebo_ros_imu_sensor.so" name="shank_imu_sensor_plugin">
        <ros>
          <namespace>/sensors</namespace>
          <remapping>~/out:=imu/shank</remapping>
        </ros>
        <frame_name>shank_link</frame_name>
        <static_reference>true</static_reference>
        <gravity>true</gravity>
        <orientation_reference_frame>ENU</orientation_reference_frame>
      </plugin>
      <imu>
        <noise>
          <type>gaussian</type>
          <rate>
            <mean>0.0</mean>
            <stddev>0.0002</stddev>
          </rate>
          <accel>
            <mean>0.0</mean>
            <stddev>0.017</stddev>
          </accel>
        </noise>
      </imu>
    </sensor>
  </gazebo>
  <gazebo reference="foot_link">
    <sensor name="foot_imu_sensor" type="imu">
      <always_on>true</always_on>
      <update_rate>100</update_rate>
      <plugin filename="libgazebo_ros_imu_sensor.so" name="foot_imu_sensor_plugin">
        <ros>
          <namespace>/sensors</namespace>
          <remapping>~/out:=imu/foot</remapping>
        </ros>
        <frame_name>foot_link</frame_name>
        <static_reference>true</static_reference>
        <gravity>true</gravity>
        <orientation_reference_frame>ENU</orientation_reference_frame>
      </plugin>
      <imu>
        <noise>
          <type>gaussian</type>
          <rate>
            <mean>0.0</mean>
            <stddev>0.0002</stddev>
          </rate>
          <accel>
            <mean>0.0</mean>
            <stddev>0.017</stddev>
          </accel>
        </noise>
      </imu>
    </sensor>
  </gazebo>
  <gazebo reference="thigh_link">
    <sensor name="hip_torque_sensor" type="force_torque">
      <update_rate>250</update_rate>
      <plugin filename="libgazebo_ros_ft_sensor.so" name="hip_torque_sensor_plugin">
        <ros>
          <namespace>/sensors</namespace>
          <remapping>~/out:=joint_forces/hip</remapping>
        </ros>
        <joint_name>hip_joint</joint_name>
        <update_rate>250</update_rate>
        <frame_name>hip_joint</frame_name>
      </plugin>
      <force_torque>
        <frame>child</frame>
        <measure_direction>child_to_parent</measure_direction>
        <noise>
          <type>gaussian</type>
          <force>
            <mean>0.0</mean>
            <stddev>0.15</stddev>
          </force>
          <torque>
            <mean>0.0</mean>
            <stddev>0.02</stddev>
          </torque>
        </noise>
      </force_torque>
    </sensor>
  </gazebo>
  <gazebo reference="shank_link">
    <sensor name="knee_torque_sensor" type="force_torque">
      <update_rate>250</update_rate>
      <plugin filename="libgazebo_ros_ft_sensor.so" name="knee_torque_sensor_plugin">
        <ros>
          <namespace>/sensors</namespace>
          <remapping>~/out:=joint_forces/knee</remapping>
        </ros>
        <joint_name>knee_joint</joint_name>
        <update_rate>250</update_rate>
        <frame_name>knee_joint</frame_name>
      </plugin>
      <force_torque>
        <frame>child</frame>
        <measure_direction>child_to_parent</measure_direction>
        <noise>
          <type>gaussian</type>
          <force>
            <mean>0.0</mean>
            <stddev>0.15</stddev>
          </force>
          <torque>
            <mean>0.0</mean>
            <stddev>0.02</stddev>
          </torque>
        </noise>
      </force_torque>
    </sensor>
  </gazebo>
  <gazebo reference="foot_link">
    <sensor name="ankle_torque_sensor" type="force_torque">
      <update_rate>250</update_rate>
      <plugin filename="libgazebo_ros_ft_sensor.so" name="ankle_torque_sensor_plugin">
        <ros>
          <namespace>/sensors</namespace>
          <remapping>~/out:=joint_forces/ankle</remapping>
        </ros>
        <joint_name>ankle_joint</joint_name>
        <update_rate>250</update_rate>
        <frame_name>ankle_joint</frame_name>
      </plugin>
      <force_torque>
        <frame>child</frame>
        <measure_direction>child_to_parent</measure_direction>
        <noise>
          <type>gaussian</type>
          <force>
            <mean>0.0</mean>
            <stddev>0.15</stddev>
          </force>
          <torque>
            <mean>0.0</mean>
            <stddev>0.02</stddev>
          </torque>
        </noise>
      </force_torque>
    </sensor>
  </gazebo>
  <!-- Contact Sensor -->
  <gazebo reference="foot_link">
    <sensor name="foot_contact" type="contact">
      <always_on>true</always_on>
      <update_rate>50</update_rate>
    </sensor>
  </gazebo>
  <gazebo>
    <plugin filename="libgazebo_ros_control.so" name="gazebo_ros_control">
      <robotNamespace>/exoskeleton</robotNamespace>
    </plugin>
  </gazebo>
</robot>
